Workbook

Sheet 2024年
A1: 6月数据
A2: 地区 | B2: 202312计费 | C2: 202312高速计费 | D2: 202312非高速计费 | E2: 202312等效计费 | F2: 202405用户数到达 | G2: 202406用户数到达 | H2: 202406计费 | I2: 202406高速计费 | J2: 202406非高速计费 | K2: 202406等效计费 | L2: 202406等效计费净增 | M2: 202406计费率 | N2: 202406已激活 | O2: 202406活跃用户 | P2: 202406活跃率 | Q2: 202406离网用户 | R2: 202406离网率
A3: 衢州 | B3: 901972 | C3: 21711 | D3: =B3-C3 -> 880261 | E3: =C3+D3/8 -> 131743.62 | F3: 3494843 | G3: 3847227 | H3: 884208 | I3: 10792 | J3: =H3-I3 -> 873416 | K3: =I3+J3/8 -> 119969 | L3: =K3-E3 -> -11774.625 | M3: =H3/G3 -> 0.22982995 | N3: 1522006 | O3: 538627 | P3: =O3/N3 -> 0.35389282 | Q3: 61770 | R3: =Q3/F3 -> 0.017674614
A4: 杭州 | B4: 10722588 | C4: 566586 | D4: =B4-C4 -> 10156002 | E4: =C4+D4/8 -> 1836086.2 | F4: 32881848 | G4: 33761672 | H4: 10498032 | I4: 743283 | J4: =H4-I4 -> 9754749 | K4: =I4+J4/8 -> 1962626.6 | L4: =K4-E4 -> 126540.38 | M4: =H4/G4 -> 0.31094526 | N4: 12103096 | O4: 6546168 | P4: =O4/N4 -> 0.54086723 | Q4: 245796 | R4: =Q4/F4 -> 0.0074751273
A5: 湖州 | B5: 2013821 | C5: 51111 | D5: =B5-C5 -> 1962710 | E5: =C5+D5/8 -> 296449.75 | F5: 7179633 | G5: 7156377 | H5: 3254185 | I5: 25876 | J5: =H5-I5 -> 3228309 | K5: =I5+J5/8 -> 429414.62 | L5: =K5-E5 -> 132964.88 | M5: =H5/G5 -> 0.45472521 | N5: 5155226 | O5: 1837302 | P5: =O5/N5 -> 0.35639601 | Q5: 99439 | R5: =Q5/F5 -> 0.013850151
A6: 嘉兴 | B6: 1786753 | C6: 17230 | D6: =B6-C6 -> 1769523 | E6: =C6+D6/8 -> 238420.38 | F6: 7658271 | G6: 8018419 | H6: 2055811 | I6: 37544 | J6: =H6-I6 -> 2018267 | K6: =I6+J6/8 -> 289827.38 | L6: =K6-E6 -> 51407 | M6: =H6/G6 -> 0.25638608 | N6: 5381346 | O6: 1108054 | P6: =O6/N6 -> 0.20590648 | Q6: 101740 | R6: =Q6/F6 -> 0.013284983
A7: 宁波 | B7: 4586610 | C7: 76827 | D7: =B7-C7 -> 4509783 | E7: =C7+D7/8 -> 640549.88 | F7: 19618386 | G7: 19803060 | H7: 6306012 | I7: 94803 | J7: =H7-I7 -> 6211209 | K7: =I7+J7/8 -> 871204.12 | L7: =K7-E7 -> 230654.25 | M7: =H7/G7 -> 0.31843624 | N7: 11456678 | O7: 4210302 | P7: =O7/N7 -> 0.36749763 | Q7: 138966 | R7: =Q7/F7 -> 0.0070834573
A8: 绍兴 | B8: 760323 | C8: 5400 | D8: =B8-C8 -> 754923 | E8: =C8+D8/8 -> 99765.375 | F8: 8723460 | G8: 8508880 | H8: 1053467 | I8: 35009 | J8: =H8-I8 -> 1018458 | K8: =I8+J8/8 -> 162316.25 | L8: =K8-E8 -> 62550.875 | M8: =H8/G8 -> 0.12380795 | N8: 4282415 | O8: 514553 | P8: =O8/N8 -> 0.12015487 | Q8: 232776 | R8: =Q8/F8 -> 0.026683908
A9: 台州 | B9: 3880521 | C9: 18998 | D9: =B9-C9 -> 3861523 | E9: =C9+D9/8 -> 501688.38 | F9: 13329253 | G9: 13479266 | H9: 3347822 | I9: 41821 | J9: =H9-I9 -> 3306001 | K9: =I9+J9/8 -> 455071.12 | L9: =K9-E9 -> -46617.25 | M9: =H9/G9 -> 0.24836827 | N9: 7203563 | O9: 1963545 | P9: =O9/N9 -> 0.27257969 | Q9: 121028 | R9: =Q9/F9 -> 0.0090798787
A10: 温州 | B10: 9944813 | C10: 56982 | D10: =B10-C10 -> 9887831 | E10: =C10+D10/8 -> 1292960.9 | F10: 25857294 | G10: 25757211 | H10: 10768159 | I10: 63338 | J10: =H10-I10 -> 10704821 | K10: =I10+J10/8 -> 1401440.6 | L10: =K10-E10 -> 108479.75 | M10: =H10/G10 -> 0.41806386 | N10: 14548546 | O10: 6890780 | P10: =O10/N10 -> 0.47364046 | Q10: 173182 | R10: =Q10/F10 -> 0.0066976073
A11: 丽水 | B11: 850721 | C11: 6857 | D11: =B11-C11 -> 843864 | E11: =C11+D11/8 -> 112340 | F11: 3260198 | G11: 3416953 | H11: 1140743 | I11: 20735 | J11: =H11-I11 -> 1120008 | K11: =I11+J11/8 -> 160736 | L11: =K11-E11 -> 48396 | M11: =H11/G11 -> 0.33384802 | N11: 1920116 | O11: 734176 | P11: =O11/N11 -> 0.38236023 | Q11: 15437 | R11: =Q11/F11 -> 0.0047349885
A12: 金华 | B12: 5226483 | C12: 102036 | D12: =B12-C12 -> 5124447 | E12: =C12+D12/8 -> 742591.88 | F12: 13863242 | G12: 14132241 | H12: 6756439 | I12: 61070 | J12: =H12-I12 -> 6695369 | K12: =I12+J12/8 -> 897991.12 | L12: =K12-E12 -> 155399.25 | M12: =H12/G12 -> 0.47808688 | N12: 9260743 | O12: 3501263 | P12: =O12/N12 -> 0.37807582 | Q12: 51233 | R12: =Q12/F12 -> 0.0036956002
A13: 舟山 | B13: 334922 | C13: 4596 | D13: =B13-C13 -> 330326 | E13: =C13+D13/8 -> 45886.75 | F13: 2573373 | G13: 2568405 | H13: 312815 | I13: 12565 | J13: =H13-I13 -> 300250 | K13: =I13+J13/8 -> 50096.25 | L13: =K13-E13 -> 4209.5 | M13: =H13/G13 -> 0.12179349 | N13: 946237 | O13: 129421 | P13: =O13/N13 -> 0.1367744 | Q13: 6874 | R13: =Q13/F13 -> 0.0026712023
A14: 全省 | B14: =SUM(B3:B13) -> 41009527 | C14: =SUM(C3:C13) -> 928334 | D14: =SUM(D3:D13) -> 40081193 | E14: =SUM(E3:E13) -> 5938483.1 | F14: =SUM(F3:F13) -> 138439801 | G14: =SUM(G3:G13) -> 140449711 | H14: =SUM(H3:H13) -> 46377693 | I14: =SUM(I3:I13) -> 1146836 | ... L14: =SUM(L3:L13) -> 862210 | M14: =H14/G14 -> 0.33020853 | N14: =SUM(N3:N13) -> 73779972 | O14: =SUM(O3:O13) -> 27974191 | P14: =O14/N14 -> 0.37915698 | Q14: =SUM(Q3:Q13) -> 1248241 | R14: =Q14/F14 -> 0.0090164894
A15: 7月数据
A16: 地区 | G16: 202407用户数到达 | H16: 202407计费 | I16: 202407高速计费 | J16: 202407非高速计费 | K16: 202407等效计费 | L16: 202407等效计费净增 | M16: 202407计费率 | N16: 202407已激活 | O16: 202407活跃用户 | P16: 202407活跃率 | Q16: 202407离网用户 | R16: 202407离网率
A17: 衢州 | G17: 3964469 | H17: 904781 | I17: 11600 | J17: =H17-I17 -> 893181 | K17: =I17+J17/8 -> 123247.62 | L17: =K17-E3 -> -8496 | M17: =H17/G17 -> 0.22822249 | N17: 1543713 | O17: 591375 | P17: =O17/N17 -> 0.3830861 | Q17: 20620 | R17: =Q17/G3 -> 0.0053597045
A18: 杭州 | G18: 33715848 | H18: 10813182 | I18: 908786 | J18: =H18-I18 -> 9904396 | K18: =I18+J18/8 -> 2146835.5 | L18: =K18-E4 -> 310749.25 | M18: =H18/G18 -> 0.32071511 | N18: 12468972 | O18: 6836802 | P18: =O18/N18 -> 0.54830519 | Q18: 405163 | R18: =Q18/G4 -> 0.012000679
A19: 湖州 | G19: 7149460 | H19: 3228307 | I19: 26328 | J19: =H19-I19 -> 3201979 | K19: =I19+J19/8 -> 426575.38 | L19: =K19-E5 -> 130125.62 | M19: =H19/G19 -> 0.45154557 | N19: 5034711 | O19: 1899526 | P19: =O19/N19 -> 0.37728601 | Q19: 35912 | R19: =Q19/G5 -> 0.0050181817
A20: 嘉兴 | G20: 8197898 | H20: 1942829 | I20: 37429 | J20: =H20-I20 -> 1905400 | K20: =I20+J20/8 -> 275604 | L20: =K20-E6 -> 37183.625 | M20: =H20/G20 -> 0.23699112 | N20: 5070966 | O20: 1141910 | P20: =O20/N20 -> 0.22518589 | Q20: 14667 | R20: =Q20/G6 -> 0.0018291636
A21: 宁波 | G21: 19810678 | H21: 6368564 | I21: 95602 | J21: =H21-I21 -> 6272962 | K21: =I21+J21/8 -> 879722.25 | L21: =K21-E7 -> 239172.38 | M21: =H21/G21 -> 0.32147128 | N21: 11893000 | O21: 4288324 | P21: =O21/N21 -> 0.36057546 | Q21: 44368 | R21: =Q21/G7 -> 0.0022404618
A22: 绍兴 | G22: 9088503 | H22: 1402885 | I22: 36139 | J22: =H22-I22 -> 1366746 | K22: =I22+J22/8 -> 206982.25 | L22: =K22-E8 -> 107216.88 | M22: =H22/G22 -> 0.1543582 | N22: 4174482 | O22: 521910 | P22: =O22/N22 -> 0.1250239 | Q22: 45197 | R22: =Q22/G8 -> 0.0053117449
A23: 台州 | G23: 13513583 | H23: 3418444 | I23: 44251 | J23: =H23-I23 -> 3374193 | K23: =I23+J23/8 -> 466025.12 | L23: =K23-E9 -> -35663.25 | M23: =H23/G23 -> 0.25296356 | N23: 7168501 | O23: 2007339 | P23: =O23/N23 -> 0.28002214 | Q23: 82759 | R23: =Q23/G9 -> 0.006139726
A24: 温州 | G24: 25612264 | H24: 9789847 | I24: 64626 | J24: =H24-I24 -> 9725221 | K24: =I24+J24/8 -> 1280278.6 | L24: =K24-E10 -> -12682.25 | M24: =H24/G24 -> 0.38223279 | N24: 14477236 | O24: 7031532 | P24: =O24/N24 -> 0.48569575 | Q24: 384295 | R24: =Q24/G10 -> 0.0149199
A25: 丽水 | G25: 3417092 | H25: 1171748 | I25: 20164 | J25: =H25-I25 -> 1151584 | K25: =I25+J25/8 -> 164112 | L25: =K25-E11 -> 51772 | M25: =H25/G25 -> 0.34290795 | N25: 1913143 | O25: 780010 | P25: =O25/N25 -> 0.40771129 | Q25: 2522 | R25: =Q25/G11 -> 0.00073808449
A26: 金华 | G26: 14419155 | H26: 7050750 | I26: 99749 | J26: =H26-I26 -> 6951001 | K26: =I26+J26/8 -> 968624.12 | L26: =K26-E12 -> 226032.25 | M26: =H26/G26 -> 0.48898496 | N26: 9367613 | O26: 3646344 | P26: =O26/N26 -> 0.38925007 | Q26: 31741 | R26: =Q26/G12 -> 0.0022459991
A27: 舟山 | G27: 2617227 | H27: 298860 | I27: 6528 | J27: =H27-I27 -> 292332 | K27: =I27+J27/8 -> 43069.5 | L27: =K27-E13 -> -2817.25 | M27: =H27/G27 -> 0.11418956 | N27: 945698 | O27: 126176 | P27: =O27/N27 -> 0.13342103 | Q27: 2099 | R27: =Q27/G13 -> 0.00081723871
A28: 全省 | G28: =SUM(G17:G27) -> 141506177 | H28: =SUM(H17:H27) -> 46390197 | I28: =SUM(I17:I27) -> 1351202 | J28: =SUM(J17:J27) -> 45038995 | K28: =SUM(K17:K27) -> 6981076.4 | L28: =SUM(L17:L27) -> 1042593.2 | M28: =H28/G28 -> 0.3278316 | N28: =SUM(N17:N27) -> 74058035 | O28: =SUM(O17:O27) -> 28871248 | P28: =O28/N28 -> 0.38984626 | Q28: =SUM(Q17:Q27) -> 1069343 | R28: =Q28/G14 -> 0.0076137074
A29: 8月数据
A30: 地区 | G30: 202408用户数到达 | H30: 202408计费 | I30: 202408高速计费 | J30: 202408非高速计费 | K30: 202408等效计费 | L30: 202408等效计费净增 | M30: 202408计费率 | N30: 202408已激活 | O30: 202408活跃用户 | P30: 202408活跃率 | Q30: 202408离网用户 | R30: 202408离网率
A31: 衢州 | G31: 4001016 | H31: 914998 | I31: 11661 | J31: =H31-I31 -> 903337 | K31: =I31+J31/8 -> 124578.12 | L31: =K31-E3 -> -7165.5 | M31: =H31/G31 -> 0.22869141 | N31: 1545831 | O31: 599944 | P31: =O31/N31 -> 0.38810452 | Q31: 72509 | R31: =Q31/G17 -> 0.018289713
A32: 杭州 | G32: 33888398 | H32: 10998775 | I32: 871306 | J32: =H32-I32 -> 10127469 | K32: =I32+J32/8 -> 2137239.6 | L32: =K32-E4 -> 301153.38 | M32: =H32/G32 -> 0.32455872 | N32: 12597781 | O32: 6949141 | P32: =O32/N32 -> 0.55161627 | Q32: 121064 | R32: =Q32/G18 -> 0.003590715
A33: 湖州 | G33: 7155021 | H33: 3240764 | I33: 26197 | J33: =H33-I33 -> 3214567 | K33: =I33+J33/8 -> 428017.88 | L33: =K33-E5 -> 131568.12 | M33: =H33/G33 -> 0.45293564 | N33: 5018587 | O33: 1972337 | P33: =O33/N33 -> 0.39300644 | Q33: 29991 | R33: =Q33/G19 -> 0.0041948623
A34: 嘉兴 | G34: 8485939 | H34: 2378087 | I34: 37808 | J34: =H34-I34 -> 2340279 | K34: =I34+J34/8 -> 330342.88 | L34: =K34-E6 -> 91922.5 | M34: =H34/G34 -> 0.28023852 | N34: 5489787 | O34: 1205626 | P34: =O34/N34 -> 0.21961253 | Q34: 4441 | R34: =Q34/G20 -> 0.00054172423
A35: 宁波 | G35: 19830048 | H35: 6421976 | I35: 96921 | J35: =H35-I35 -> 6325055 | K35: =I35+J35/8 -> 887552.88 | L35: =K35-E7 -> 247003 | M35: =H35/G35 -> 0.32385075 | N35: 12167045 | O35: 4321405 | P35: =O35/N35 -> 0.35517293 | Q35: 47712 | R35: =Q35/G21 -> 0.0024083981
A36: 绍兴 | G36: 9132199 | H36: 1242364 | I36: 35386 | J36: =H36-I36 -> 1206978 | K36: =I36+J36/8 -> 186258.25 | L36: =K36-E8 -> 86492.875 | M36: =H36/G36 -> 0.13604215 | N36: 4201924 | O36: 523424 | P36: =O36/N36 -> 0.1245677 | Q36: 50159 | R36: =Q36/G22 -> 0.0055189507
A37: 台州 | G37: 13567443 | H37: 3459367 | I37: 43528 | J37: =H37-I37 -> 3415839 | K37: =I37+J37/8 -> 470507.88 | L37: =K37-E9 -> -31180.5 | M37: =H37/G37 -> 0.25497561 | N37: 7328909 | O37: 2006946 | P37: =O37/N37 -> 0.27383967 | Q37: 60169 | R37: =Q37/G23 -> 0.0044524831
A38: 温州 | G38: 25349492 | H38: 10825223 | I38: 67825 | J38: =H38-I38 -> 10757398 | K38: =I38+J38/8 -> 1412499.8 | L38: =K38-E10 -> 119538.88 | M38: =H38/G38 -> 0.42703905 | N38: 14529026 | O38: 7025177 | P38: =O38/N38 -> 0.48352704 | Q38: 324621 | R38: =Q38/G24 -> 0.012674436
A39: 丽水 | G39: 3416303 | H39: 1142236 | I39: 20186 | J39: =H39-I39 -> 1122050 | K39: =I39+J39/8 -> 160442.25 | L39: =K39-E11 -> 48102.25 | M39: =H39/G39 -> 0.33434856 | N39: 1906810 | O39: 766342 | P39: =O39/N39 -> 0.40189741 | Q39: 4132 | R39: =Q39/G25 -> 0.0012092153
A40: 金华 | G40: 14528437 | H40: 7440222 | I40: 59687 | J40: =H40-I40 -> 7380535 | K40: =I40+J40/8 -> 982253.88 | L40: =K40-E12 -> 239662 | M40: =H40/G40 -> 0.51211441 | N40: 9818246 | O40: 3689980 | P40: =O40/N40 -> 0.37582884 | Q40: 413424 | R40: =Q40/G26 -> 0.02867186
...

Sheet 2025年
A1: 1月数据
A2: 地市 | B2: 202412用户数到达 | C2: 202412计费 | D2: 202501用户数到达 | E2: 202501计费 | F2: 202501计费净增 | G2: 202501高速计费 | H2: 202501非高速计费 | I2: 202501等效计费 | J2: 202501等效计费净增 | K2: 202501计费率 | L2: 202501已激活 | M2: 202501活跃用户 | N2: 202501活跃率 | O2: 202501离网用户 | P2: 202501离网率
A3: 衢州 | B3: 4369377 | C3: 998225 | D3: 4170618 | E3: 1254627 | F3: =E3-C3 -> 256402 | G3: 13822 | H3: 1240805 | I3: =G3+H3/8 -> 168922.62 | J3: =I3-'2024年'!K87 -> 31931.25 | K3: =E3/D3 -> 0.3008252 | L3: 2491562 | M3: 729074 | N3: =M3/L3 -> 0.29261724 | O3: 221381 | P3: =O3/B3 -> 0.050666491
A4: 杭州 | B4: 33882675 | C4: 11563661 | D4: 33950995 | E4: 12125083 | F4: =E4-C4 -> 561422 | G4: 824940 | H4: 11300143 | I4: =G4+H4/8 -> 2237457.9 | J4: =I4-'2024年'!K88 -> -47239.375 | K4: =E4/D4 -> 0.35713484 | L4: 13420022 | M4: 7802279 | N4: =M4/L4 -> 0.58139092 | O4: 236005 | P4: =O4/B4 -> 0.0069653591
A5: 湖州 | B5: 7463675 | C5: 3523545 | D5: 7390030 | E5: 3899953 | F5: =E5-C5 -> 376408 | G5: 29008 | H5: 3870945 | I5: =G5+H5/8 -> 512876.12 | J5: =I5-'2024年'!K89 -> 47238.25 | K5: =E5/D5 -> 0.52773169 | L5: 5077051 | M5: 2461129 | N5: =M5/L5 -> 0.48475562 | O5: 150134 | P5: =O5/B5 -> 0.020115292
A6: 嘉兴 | B6: 9262105 | C6: 2902443 | D6: 9312584 | E6: 2958999 | F6: =E6-C6 -> 56556 | G6: 40094 | H6: 2918905 | I6: =G6+H6/8 -> 404957.12 | J6: =I6-'2024年'!K90 -> 8249 | K6: =E6/D6 -> 0.31774199 | L6: 6468628 | M6: 1446089 | N6: =M6/L6 -> 0.22355421 | O6: 26866 | P6: =O6/B6 -> 0.0029006365
A7: 宁波 | B7: 20022474 | C7: 6530408 | D7: 20051454 | E7: 6799240 | F7: =E7-C7 -> 268832 | G7: 104957 | H7: 6694283 | I7: =G7+H7/8 -> 941742.38 | J7: =I7-'2024年'!K91 -> 32884.75 | K7: =E7/D7 -> 0.33908962 | L7: 13692995 | M7: 4591653 | N7: =M7/L7 -> 0.33532861 | O7: 54992 | P7: =O7/B7 -> 0.0027465137
A8: 绍兴 | B8: 9703575 | C8: 1114643 | D8: 9656196 | E8: 1259226 | F8: =E8-C8 -> 144583 | G8: 38919 | H8: 1220307 | I8: =G8+H8/8 -> 191457.38 | J8: =I8-'2024年'!K92 -> 18575.125 | K8: =E8/D8 -> 0.13040601 | L8: 4489138 | M8: 476561 | N8: =M8/L8 -> 0.10615869 | O8: 52373 | P8: =O8/B8 -> 0.0053972891
A9: 台州 | B9: 14058978 | C9: 3183026 | D9: 13909224 | E9: 3350731 | F9: =E9-C9 -> 167705 | G9: 44708 | H9: 3306023 | I9: =G9+H9/8 -> 457960.88 | J9: =I9-'2024年'!K93 -> 20075 | K9: =E9/D9 -> 0.24089992 | L9: 7737013 | M9: 2061207 | N9: =M9/L9 -> 0.26640863 | O9: 335783 | P9: =O9/B9 -> 0.023883884
A10: 温州 | B10: 25818295 | C10: 10012594 | D10: 25656949 | E10: 10049257 | F10: =E10-C10 -> 36663 | G10: 74967 | H10: 9974290 | I10: =G10+H10/8 -> 1321753.2 | J10: =I10-'2024年'!K94 -> 6521.875 | K10: =E10/D10 -> 0.39167779 | L10: 15545490 | M10: 7018407 | N10: =M10/L10 -> 0.45147544 | O10: 185505 | P10: =O10/B10 -> 0.0071850213
A11: 丽水 | B11: 4044113 | C11: 1145147 | D11: 3936475 | E11: 1152533 | F11: =E11-C11 -> 7386 | G11: 21314 | H11: 1131219 | I11: =G11+H11/8 -> 162716.38 | J11: =I11-'2024年'!K95 -> 898.75 | K11: =E11/D11 -> 0.29278301 | L11: 1842940 | M11: 670986 | N11: =M11/L11 -> 0.36408456 | O11: 109404 | P11: =O11/B11 -> 0.027052657
A12: 金华 | B12: 15748418 | C12: 7871164 | D12: 15880080 | E12: 8276821 | F12: =E12-C12 -> 405657 | G12: 102086 | H12: 8174735 | I12: =G12+H12/8 -> 1123927.9 | J12: =I12-'2024年'!K96 -> 86324 | K12: =E12/D12 -> 0.52120776 | L12: 11593154 | M12: 3921002 | N12: =M12/L12 -> 0.33821702 | O12: 294701 | P12: =O12/B12 -> 0.018713054
A13: 舟山 | B13: 2970142 | C13: 324109 | D13: 2967715 | E13: 311005 | F13: =E13-C13 -> -13104 | G13: 6982 | H13: 304023 | I13: =G13+H13/8 -> 44984.875 | J13: =I13-'2024年'!K97 -> -1308.125 | K13: =E13/D13 -> 0.10479611 | L13: 1712570 | M13: 110900 | N13: =M13/L13 -> 0.064756477 | O13: 2782 | P13: =O13/B13 -> 0.00093665555
A14: 全省 | B14: =SUM(B3:B13) -> 147343827 | C14: =SUM(C3:C13) -> 49168965 | D14: =SUM(D3:D13) -> 146882320 | E14: =SUM(E3:E13) -> 51437475 | F14: =E14-C14 -> 2268510 | G14: =SUM(G3:G13) -> 1301797 | H14: =E14-G14 -> 50135678 | I14: =G14+H14/8 -> 7568756.8 | J14: =I14-'2024年'!K98 -> 204150.5 | K14: =E14/D14 -> 0.35019514 | L14: =SUM(L3:L13) -> 84070563 | M14: =SUM(M3:M13) -> 31289287 | N14: =M14/L14 -> 0.37217887 | O14: =SUM(O3:O13) -> 1669926 | P14: =O14/B14 -> 0.011333532
A15: 2月数据
A16: 地市 | D16: 202502用户数到达 | E16: 202502计费 | F16: 202502计费净增 | G16: 202402计费 | H16: 202502计费同比增加 | I16: 202502计费同比增加百分比 | J16: 202502计费率 | L16: 202502已激活 | M16: 202502活跃用户 | N16: 202502活跃率 | O16: 202502离网用户 | P16: 202502离网率
A17: 衢州 | D17: 4158757 | E17: 1292420 | F17: =E17-C3 -> 294195 | G17: 1099787 | H17: =E17-G17 -> 192633 | I17: =H17/G17 -> 0.17515483 | J17: =E17/D17 -> 0.31077074 | L17: 2540591 | M17: 742597 | N17: =M17/L17 -> 0.29229301 | O17: 16045 | P17: =O17/D3 -> 0.0038471517
A18: 杭州 | D18: 34097120 | E18: 12122663 | F18: =E18-C4 -> 559002 | G18: 10332891 | H18: =E18-G18 -> 1789772 | I18: =H18/G18 -> 0.17321116 | J18: =E18/D18 -> 0.35553334 | L18: 13813800 | M18: 7813429 | N18: =M18/L18 -> 0.56562488 | O18: 95548 | P18: =O18/D4 -> 0.0028142916
A19: 湖州 | D19: 7308885 | E19: 3990460 | F19: =E19-C5 -> 466915 | G19: 2630253 | H19: =E19-G19 -> 1360207 | I19: =H19/G19 -> 0.51713923 | J19: =E19/D19 -> 0.54597384 | L19: 5255145 | M19: 2421091 | N19: =M19/L19 -> 0.4607087 | O19: 144839 | P19: =O19/D5 -> 0.019599244
A20: 嘉兴 | D20: 9365958 | E20: 3227355 | F20: =E20-C6 -> 324912 | G20: 1968327 | H20: =E20-G20 -> 1259028 | I20: =H20/G20 -> 0.63964372 | J20: =E20/D20 -> 0.34458354 | L20: 6673640 | M20: 1484252 | N20: =M20/L20 -> 0.22240516 | O20: 249470 | P20: =O20/D6 -> 0.026788483
A21: 宁波 | D21: 20262655 | E21: 7125387 | F21: =E21-C7 -> 594979 | G21: 5982644 | H21: =E21-G21 -> 1142743 | I21: =H21/G21 -> 0.19100969 | J21: =E21/D21 -> 0.3516512 | L21: 13638869 | M21: 4607207 | N21: =M21/L21 -> 0.33779978 | O21: 64812 | P21: =O21/D7 -> 0.0032322843
A22: 绍兴 | D22: 9355243 | E22: 1549610 | F22: =E22-C8 -> 434967 | G22: 1297429 | H22: =E22-G22 -> 252181 | I22: =H22/G22 -> 0.19436979 | J22: =E22/D22 -> 0.16564081 | L22: 4252008 | M22: 467918 | N22: =M22/L22 -> 0.11004636 | O22: 654069 | P22: =O22/D8 -> 0.06773568
A23: 台州 | D23: 14139837 | E23: 3286553 | F23: =E23-C9 -> 103527 | G23: 3917259 | H23: =E23-G23 -> -630706 | I23: =H23/G23 -> -0.16100697 | J23: =E23/D23 -> 0.23243217 | L23: 7951843 | M23: 2002203 | N23: =M23/L23 -> 0.25179106 | O23: 10879 | P23: =O23/D9 -> 0.00078214284
A24: 温州 | D24: 25460057 | E24: 11128654 | F24: =E24-C10 -> 1116060 | G24: 10336033 | H24: =E24-G24 -> 792621 | I24: =H24/G24 -> 0.076685223 | J24: =E24/D24 -> 0.43710248 | L24: 16271013 | M24: 6979954 | N24: =M24/L24 -> 0.42898091 | O24: 225748 | P24: =O24/D10 -> 0.0087987079
A25: 丽水 | D25: 3914645 | E25: 1139904 | F25: =E25-C11 -> -5243 | G25: 948130 | H25: =E25-G25 -> 191774 | I25: =H25/G25 -> 0.20226551 | J25: =E25/D25 -> 0.29118962 | L25: 1747739 | M25: 655891 | N25: =M25/L25 -> 0.37527972 | O25: 24301 | P25: =O25/D11 -> 0.0061732896
A26: 金华 | D26: 16023317 | E26: 8402178 | F26: =E26-C12 -> 531014 | G26: 5807125 | H26: =E26-G26 -> 2595053 | I26: =H26/G26 -> 0.44687397 | J26: =E26/D26 -> 0.52437195 | L26: 11829136 | M26: 3711076 | N26: =M26/L26 -> 0.31372334 | O26: 255778 | P26: =O26/D12 -> 0.016106846
A27: 舟山 | D27: 2967160 | E27: 267797 | F27: =E27-C13 -> -56312 | G27: 331647 | H27: =E27-G27 -> -63850 | I27: =H27/G27 -> -0.19252398 | J27: =E27/D27 -> 0.090253643 | L27: 1669971 | M27: 108115 | N27: =M27/L27 -> 0.064740645 | O27: 1782 | P27: =O27/D13 -> 0.00060046197
A28: 全省 | D28: =SUM(D17:D27) -> 147053634 | E28: =SUM(E17:E27) -> 53532981 | F28: =E28-C14 -> 4364016 | G28: =SUM(G17:G27) -> 44651525 | H28: =E28-G28 -> 8881456 | I28: =H28/G28 -> 0.19890599 | J28: =E28/D28 -> 0.36403712 | L28: =SUM(L17:L27) -> 85643755 | M28: =SUM(M17:M27) -> 30993733 | N28: =M28/L28 -> 0.36189134 | O28: =SUM(O17:O27) -> 1743271 | P28: =O28/D14 -> 0.011868488
A29: 3月数据
A30: 地市 | D30: 202503用户数到达 | E30: 202503计费 | F30: 202503计费净增 | G30: 202403计费 | H30: 202503计费同比增加 | I30: 202503计费同比增加百分比 | J30: 202503计费率 | L30: 202503已激活 | M30: 202503活跃用户 | N30: 202503活跃率 | O30: 202503离网用户 | P30: 202503离网率
A31: 衢州 | D31: 3937738 | E31: 1561164 | F31: =E31-C3 -> 562939 | G31: 1109908 | H31: =E31-G31 -> 451256 | I31: =H31/G31 -> 0.40657063 | J31: =E31/D31 -> 0.39646213 | L31: 2788325 | M31: 775505 | N31: =M31/L31 -> 0.27812576 | O31: 263705 | P31: =O31/D17 -> 0.063409572
A32: 杭州 | D32: 33957175 | E32: 12557595 | F32: =E32-C4 -> 993934 | G32: 11102682 | H32: =E32-G32 -> 1454913 | I32: =H32/G32 -> 0.13104158 | J32: =E32/D32 -> 0.36980682 | L32: 14181176 | M32: 8202555 | N32: =M32/L32 -> 0.57841148 | O32: 778671 | P32: =O32/D18 -> 0.022836855
A33: 湖州 | D33: 7559664 | E33: 4128771 | F33: =E33-C5 -> 605226 | G33: 2992818 | H33: =E33-G33 -> 1135953 | I33: =H33/G33 -> 0.37955967 | J33: =E33/D33 -> 0.546158 | L33: 5492972 | M33: 2522706 | N33: =M33/L33 -> 0.45926067 | O33: 31381 | P33: =O33/D19 -> 0.0042935414
A34: 嘉兴 | D34: 8829778 | E34: 3537074 | F34: =E34-C6 -> 634631 | G34: 2189796 | H34: =E34-G34 -> 1347278 | I34: =H34/G34 -> 0.61525275 | J34: =E34/D34 -> 0.4005847 | L34: 6651168 | M34: 1667515 | N34: =M34/L34 -> 0.2507101 | O34: 600403 | P34: =O34/D20 -> 0.064104814
A35: 宁波 | D35: 20142549 | E35: 7197762 | F35: =E35-C7 -> 667354 | G35: 6522289 | H35: =E35-G35 -> 675473 | I35: =H35/G35 -> 0.10356379 | J35: =E35/D35 -> 0.35734117 | L35: 13287349 | M35: 4785577 | N35: =M35/L35 -> 0.36016041 | O35: 231556 | P35: =O35/D21 -> 0.011427723
A36: 绍兴 | D36: 9236602 | E36: 1491668 | F36: =E36-C8 -> 377025 | G36: 1363925 | H36: =E36-G36 -> 127743 | I36: =H36/G36 -> 0.093658376 | J36: =E36/D36 -> 0.16149532 | L36: 4230585 | M36: 476177 | N36: =M36/L36 -> 0.11255583 | O36: 171768 | P36: =O36/D22 -> 0.018360613
A37: 台州 | D37: 14160910 | E37: 3137927 | F37: =E37-C9 -> -45099 | G37: 3788872 | H37: =E37-G37 -> -650945 | I37: =H37/G37 -> -0.17180443 | J37: =E37/D37 -> 0.22159077 | L37: 8113508 | M37: 2080867 | N37: =M37/L37 -> 0.25646946 | O37: 331522 | P37: =O37/D23 -> 0.023445956
A38: 温州 | D38: 25105581 | E38: 11083469 | F38: =E38-C10 -> 1070875 | G38: 10740766 | H38: =E38-G38 -> 342703 | I38: =H38/G38 -> 0.031906756 | J38: =E38/D38 -> 0.44147431 | L38: 16330761 | M38: 7185923 | N38: =M38/L38 -> 0.44002377 | O38: 608238 | P38: =O38/D24 -> 0.023889892
A39: 丽水 | D39: 3895070 | E39: 1141694 | F39: =E39-C11 -> -3453 | G39: 998785 | H39: =E39-G39 -> 142909 | I39: =H39/G39 -> 0.14308285 | J39: =E39/D39 -> 0.29311258 | L39: 1745069 | M39: 656032 | N39: =M39/L39 -> 0.37593471 | O39: 22655 | P39: =O39/D25 -> 0.0057872425
A40: 金华 | D40: 16279144 | E40: 8643196 | F40: =E40-C12 -> 772032 | G40: 6362853 | H40: =E40-G40 -> 2280343 | I40: =H40/G40 -> 0.35838373 | J40: =E40/D40 -> 0.53093676 | L40: 12120551 | M40: 3929887 | N40: =M40/L40 -> 0.32423336 | O40: 234123 | P40: =O40/D26 -> 0.014611394
...
